<robot name="fourLinks">
    <link name="base_link" />
   <joint name="base_fixed_joint" type="fixed">
        <origin xyz="0 0 0" rpy="0 -0 0" />
        <axis xyz="0 0 0" />
        <parent link="base_link" />
        <child link="link1" />
    </joint>
    <link name="link1">
        <inertial>
            <mass value="10" />
            <inertia ixx="0.01" ixy="0.0" ixz="0.0" iyy="0.01" iyz="0.0" izz="0.01" />
        </inertial>
    </link>
    <joint name="joint_1_2" type="continuous">
        <origin xyz="0 1 0" rpy="0 -0 0" />
        <axis xyz="1 0 0" />
        <parent link="link1" />
        <child link="link2" />
    </joint>
    <link name="link2">
        <inertial>
            <mass value="10" />
            <inertia ixx="1.0" ixy="0.0" ixz="0.0" iyy="1.0" iyz="0.0" izz="1.0" />
            <origin xyz="0.0 0.0 0" rpy="0 -0 0" />
        </inertial>
    </link>
    <joint name="joint_2_3" type="continuous">
        <origin xyz="0 0 1" rpy="0 -0 0" />
        <axis xyz="0 1 0" />
        <parent link="link2" />
        <child link="link3" />
    </joint>
    <link name="link3">
        <inertial>
            <mass value="10" />
            <inertia ixx="1.0" ixy="0.0" ixz="0.0" iyy="1.0" iyz="0.0" izz="1.0" />
            <origin xyz="0.0 0.0 0" rpy="0 -0 0" />
        </inertial>
    </link>
    <joint name="joint_3_4" type="continuous">
        <origin xyz="1 0 0" rpy="0 -0 0" />
        <axis xyz="0 0 1" />
        <parent link="link3" />
        <child link="link4" />
    </joint>
    <link name="link4">
        <inertial>
            <mass value="10" />
            <inertia ixx="1.0" ixy="0.0" ixz="0.0" iyy="1.0" iyz="0.0" izz="1.0" />
            <origin xyz="0.0 0.0 0" rpy="0 -0 0" />
        </inertial>
    </link>
</robot>
